[2025-07-25T19:07:31.927+0000] {local_task_job_runner.py:120} INFO - ::group::Pre task execution logs
[2025-07-25T19:07:31.941+0000] {taskinstance.py:2076} INFO - Dependencies all met for dep_context=non-requeueable deps ti=<TaskInstance: dnc_pipeline.executar_pipeline_etl manual__2025-07-25T19:02:28.965268+00:00 [queued]>
[2025-07-25T19:07:31.945+0000] {taskinstance.py:2076} INFO - Dependencies all met for dep_context=requeueable deps ti=<TaskInstance: dnc_pipeline.executar_pipeline_etl manual__2025-07-25T19:02:28.965268+00:00 [queued]>
[2025-07-25T19:07:31.945+0000] {taskinstance.py:2306} INFO - Starting attempt 2 of 2
[2025-07-25T19:07:31.951+0000] {taskinstance.py:2330} INFO - Executing <Task(PythonOperator): executar_pipeline_etl> on 2025-07-25 19:02:28.965268+00:00
[2025-07-25T19:07:31.954+0000] {standard_task_runner.py:63} INFO - Started process 181 to run task
[2025-07-25T19:07:31.957+0000] {standard_task_runner.py:90} INFO - Running: ['***', 'tasks', 'run', 'dnc_pipeline', 'executar_pipeline_etl', 'manual__2025-07-25T19:02:28.965268+00:00', '--job-id', '15', '--raw', '--subdir', 'DAGS_FOLDER/dnc_pipeline_dag.py', '--cfg-path', '/tmp/tmp4jtgfbbb']
[2025-07-25T19:07:31.958+0000] {standard_task_runner.py:91} INFO - Job 15: Subtask executar_pipeline_etl
[2025-07-25T19:07:31.982+0000] {task_command.py:426} INFO - Running <TaskInstance: dnc_pipeline.executar_pipeline_etl manual__2025-07-25T19:02:28.965268+00:00 [running]> on host 0aa6ac183a08
[2025-07-25T19:07:32.142+0000] {taskinstance.py:2648} INFO - Exporting env vars: AIRFLOW_CTX_DAG_OWNER='***' AIRFLOW_CTX_DAG_ID='dnc_pipeline' AIRFLOW_CTX_TASK_ID='executar_pipeline_etl' AIRFLOW_CTX_EXECUTION_DATE='2025-07-25T19:02:28.965268+00:00' AIRFLOW_CTX_TRY_NUMBER='2' AIRFLOW_CTX_DAG_RUN_ID='manual__2025-07-25T19:02:28.965268+00:00'
[2025-07-25T19:07:32.143+0000] {taskinstance.py:430} INFO - ::endgroup::
[2025-07-25T19:07:32.159+0000] {credentials.py:1147} INFO - Found credentials in environment variables.
[2025-07-25T19:07:35.423+0000] {taskinstance.py:441} INFO - ::group::Post task execution logs
[2025-07-25T19:07:35.423+0000] {taskinstance.py:2905} ERROR - Task failed with exception
Traceback (most recent call last):
  File "/home/airflow/.local/lib/python3.10/site-packages/airflow/models/taskinstance.py", line 465, in _execute_task
    result = _execute_callable(context=context, **execute_callable_kwargs)
  File "/home/airflow/.local/lib/python3.10/site-packages/airflow/models/taskinstance.py", line 432, in _execute_callable
    return execute_callable(context=context, **execute_callable_kwargs)
  File "/home/airflow/.local/lib/python3.10/site-packages/airflow/models/baseoperator.py", line 400, in wrapper
    return func(self, *args, **kwargs)
  File "/home/airflow/.local/lib/python3.10/site-packages/airflow/operators/python.py", line 235, in execute
    return_value = self.execute_callable()
  File "/home/airflow/.local/lib/python3.10/site-packages/airflow/operators/python.py", line 252, in execute_callable
    return self.python_callable(*self.op_args, **self.op_kwargs)
  File "/opt/airflow/dags/etl_pipeline.py", line 18, in run_etl
    salvar_parquet(df_bronze, "/opt/airflow/dados/bronze/usuarios_bronze.parquet")
  File "/opt/airflow/dags/etl_pipeline.py", line 12, in salvar_parquet
    df.to_parquet(caminho, index=False)
  File "/home/airflow/.local/lib/python3.10/site-packages/pandas/core/frame.py", line 2970, in to_parquet
    return to_parquet(
  File "/home/airflow/.local/lib/python3.10/site-packages/pandas/io/parquet.py", line 483, in to_parquet
    impl.write(
  File "/home/airflow/.local/lib/python3.10/site-packages/pandas/io/parquet.py", line 197, in write
    path_or_handle, handles, filesystem = _get_path_or_handle(
  File "/home/airflow/.local/lib/python3.10/site-packages/pandas/io/parquet.py", line 139, in _get_path_or_handle
    handles = get_handle(
  File "/home/airflow/.local/lib/python3.10/site-packages/pandas/io/common.py", line 739, in get_handle
    check_parent_directory(str(handle))
  File "/home/airflow/.local/lib/python3.10/site-packages/pandas/io/common.py", line 604, in check_parent_directory
    raise OSError(rf"Cannot save file into a non-existent directory: '{parent}'")
OSError: Cannot save file into a non-existent directory: '/opt/***/dados/bronze'
[2025-07-25T19:07:35.442+0000] {taskinstance.py:1206} INFO - Marking task as FAILED. dag_id=dnc_pipeline, task_id=executar_pipeline_etl, run_id=manual__2025-07-25T19:02:28.965268+00:00, execution_date=20250725T190228, start_date=20250725T190731, end_date=20250725T190735
[2025-07-25T19:07:35.453+0000] {standard_task_runner.py:110} ERROR - Failed to execute job 15 for task executar_pipeline_etl (Cannot save file into a non-existent directory: '/opt/***/dados/bronze'; 181)
[2025-07-25T19:07:35.464+0000] {local_task_job_runner.py:240} INFO - Task exited with return code 1
[2025-07-25T19:07:35.474+0000] {taskinstance.py:3498} INFO - 0 downstream tasks scheduled from follow-on schedule check
[2025-07-25T19:07:35.474+0000] {local_task_job_runner.py:222} INFO - ::endgroup::
