[2025-07-25T19:04:19.032+0000] {local_task_job_runner.py:120} INFO - ::group::Pre task execution logs
[2025-07-25T19:04:19.047+0000] {taskinstance.py:2076} INFO - Dependencies all met for dep_context=non-requeueable deps ti=<TaskInstance: dnc_pipeline.executar_pipeline_etl manual__2025-07-25T19:04:17.733260+00:00 [queued]>
[2025-07-25T19:04:19.050+0000] {taskinstance.py:2076} INFO - Dependencies all met for dep_context=requeueable deps ti=<TaskInstance: dnc_pipeline.executar_pipeline_etl manual__2025-07-25T19:04:17.733260+00:00 [queued]>
[2025-07-25T19:04:19.050+0000] {taskinstance.py:2306} INFO - Starting attempt 1 of 2
[2025-07-25T19:04:19.055+0000] {taskinstance.py:2330} INFO - Executing <Task(PythonOperator): executar_pipeline_etl> on 2025-07-25 19:04:17.733260+00:00
[2025-07-25T19:04:19.058+0000] {standard_task_runner.py:63} INFO - Started process 202 to run task
[2025-07-25T19:04:19.060+0000] {standard_task_runner.py:90} INFO - Running: ['***', 'tasks', 'run', 'dnc_pipeline', 'executar_pipeline_etl', 'manual__2025-07-25T19:04:17.733260+00:00', '--job-id', '13', '--raw', '--subdir', 'DAGS_FOLDER/dnc_pipeline_dag.py', '--cfg-path', '/tmp/tmpmp3kv7lr']
[2025-07-25T19:04:19.061+0000] {standard_task_runner.py:91} INFO - Job 13: Subtask executar_pipeline_etl
[2025-07-25T19:04:19.086+0000] {task_command.py:426} INFO - Running <TaskInstance: dnc_pipeline.executar_pipeline_etl manual__2025-07-25T19:04:17.733260+00:00 [running]> on host 8e6ae60113e1
[2025-07-25T19:04:19.228+0000] {taskinstance.py:2648} INFO - Exporting env vars: AIRFLOW_CTX_DAG_OWNER='***' AIRFLOW_CTX_DAG_ID='dnc_pipeline' AIRFLOW_CTX_TASK_ID='executar_pipeline_etl' AIRFLOW_CTX_EXECUTION_DATE='2025-07-25T19:04:17.733260+00:00' AIRFLOW_CTX_TRY_NUMBER='1' AIRFLOW_CTX_DAG_RUN_ID='manual__2025-07-25T19:04:17.733260+00:00'
[2025-07-25T19:04:19.228+0000] {taskinstance.py:430} INFO - ::endgroup::
[2025-07-25T19:04:19.238+0000] {credentials.py:1147} INFO - Found credentials in environment variables.
[2025-07-25T19:04:19.773+0000] {taskinstance.py:441} INFO - ::group::Post task execution logs
[2025-07-25T19:04:19.774+0000] {taskinstance.py:2905} ERROR - Task failed with exception
Traceback (most recent call last):
  File "/home/airflow/.local/lib/python3.10/site-packages/airflow/models/taskinstance.py", line 465, in _execute_task
    result = _execute_callable(context=context, **execute_callable_kwargs)
  File "/home/airflow/.local/lib/python3.10/site-packages/airflow/models/taskinstance.py", line 432, in _execute_callable
    return execute_callable(context=context, **execute_callable_kwargs)
  File "/home/airflow/.local/lib/python3.10/site-packages/airflow/models/baseoperator.py", line 400, in wrapper
    return func(self, *args, **kwargs)
  File "/home/airflow/.local/lib/python3.10/site-packages/airflow/operators/python.py", line 235, in execute
    return_value = self.execute_callable()
  File "/home/airflow/.local/lib/python3.10/site-packages/airflow/operators/python.py", line 252, in execute_callable
    return self.python_callable(*self.op_args, **self.op_kwargs)
  File "/opt/airflow/dags/etl_pipeline.py", line 16, in run_etl
    df_raw = read_raw_csv_from_s3("dnc-pipeline-rid211401", "raw_data.csv")
  File "/opt/airflow/dags/etl_pipeline.py", line 8, in read_raw_csv_from_s3
    obj = s3.get_object(Bucket=bucket_name, Key=key)
  File "/home/airflow/.local/lib/python3.10/site-packages/botocore/client.py", line 553, in _api_call
    return self._make_api_call(operation_name, kwargs)
  File "/home/airflow/.local/lib/python3.10/site-packages/botocore/client.py", line 1009, in _make_api_call
    raise error_class(parsed_response, operation_name)
botocore.errorfactory.NoSuchBucket: An error occurred (NoSuchBucket) when calling the GetObject operation: The specified bucket does not exist
[2025-07-25T19:04:19.785+0000] {taskinstance.py:1206} INFO - Marking task as UP_FOR_RETRY. dag_id=dnc_pipeline, task_id=executar_pipeline_etl, run_id=manual__2025-07-25T19:04:17.733260+00:00, execution_date=20250725T190417, start_date=20250725T190419, end_date=20250725T190419
[2025-07-25T19:04:19.797+0000] {standard_task_runner.py:110} ERROR - Failed to execute job 13 for task executar_pipeline_etl (An error occurred (NoSuchBucket) when calling the GetObject operation: The specified bucket does not exist; 202)
[2025-07-25T19:04:19.809+0000] {local_task_job_runner.py:240} INFO - Task exited with return code 1
[2025-07-25T19:04:19.815+0000] {local_task_job_runner.py:222} INFO - ::endgroup::
