[2025-07-25T18:44:57.306+0000] {local_task_job_runner.py:120} INFO - ::group::Pre task execution logs
[2025-07-25T18:44:57.321+0000] {taskinstance.py:2076} INFO - Dependencies all met for dep_context=non-requeueable deps ti=<TaskInstance: dnc_pipeline.executar_pipeline_etl manual__2025-07-25T18:44:56.147161+00:00 [queued]>
[2025-07-25T18:44:57.324+0000] {taskinstance.py:2076} INFO - Dependencies all met for dep_context=requeueable deps ti=<TaskInstance: dnc_pipeline.executar_pipeline_etl manual__2025-07-25T18:44:56.147161+00:00 [queued]>
[2025-07-25T18:44:57.325+0000] {taskinstance.py:2306} INFO - Starting attempt 1 of 2
[2025-07-25T18:44:57.330+0000] {taskinstance.py:2330} INFO - Executing <Task(PythonOperator): executar_pipeline_etl> on 2025-07-25 18:44:56.147161+00:00
[2025-07-25T18:44:57.333+0000] {standard_task_runner.py:63} INFO - Started process 199 to run task
[2025-07-25T18:44:57.335+0000] {standard_task_runner.py:90} INFO - Running: ['***', 'tasks', 'run', 'dnc_pipeline', 'executar_pipeline_etl', 'manual__2025-07-25T18:44:56.147161+00:00', '--job-id', '6', '--raw', '--subdir', 'DAGS_FOLDER/dnc_pipeline_dag.py', '--cfg-path', '/tmp/tmppkf3elfx']
[2025-07-25T18:44:57.336+0000] {standard_task_runner.py:91} INFO - Job 6: Subtask executar_pipeline_etl
[2025-07-25T18:44:57.365+0000] {task_command.py:426} INFO - Running <TaskInstance: dnc_pipeline.executar_pipeline_etl manual__2025-07-25T18:44:56.147161+00:00 [running]> on host 61ad4689b739
[2025-07-25T18:44:57.523+0000] {taskinstance.py:2648} INFO - Exporting env vars: AIRFLOW_CTX_DAG_OWNER='***' AIRFLOW_CTX_DAG_ID='dnc_pipeline' AIRFLOW_CTX_TASK_ID='executar_pipeline_etl' AIRFLOW_CTX_EXECUTION_DATE='2025-07-25T18:44:56.147161+00:00' AIRFLOW_CTX_TRY_NUMBER='1' AIRFLOW_CTX_DAG_RUN_ID='manual__2025-07-25T18:44:56.147161+00:00'
[2025-07-25T18:44:57.524+0000] {taskinstance.py:430} INFO - ::endgroup::
[2025-07-25T18:44:59.677+0000] {taskinstance.py:441} INFO - ::group::Post task execution logs
[2025-07-25T18:44:59.678+0000] {taskinstance.py:2905} ERROR - Task failed with exception
Traceback (most recent call last):
  File "/home/airflow/.local/lib/python3.10/site-packages/airflow/models/taskinstance.py", line 465, in _execute_task
    result = _execute_callable(context=context, **execute_callable_kwargs)
  File "/home/airflow/.local/lib/python3.10/site-packages/airflow/models/taskinstance.py", line 432, in _execute_callable
    return execute_callable(context=context, **execute_callable_kwargs)
  File "/home/airflow/.local/lib/python3.10/site-packages/airflow/models/baseoperator.py", line 400, in wrapper
    return func(self, *args, **kwargs)
  File "/home/airflow/.local/lib/python3.10/site-packages/airflow/operators/python.py", line 235, in execute
    return_value = self.execute_callable()
  File "/home/airflow/.local/lib/python3.10/site-packages/airflow/operators/python.py", line 252, in execute_callable
    return self.python_callable(*self.op_args, **self.op_kwargs)
  File "/opt/airflow/dags/etl_pipeline.py", line 16, in run_etl
    df_raw = read_raw_csv_from_s3("dnc-pipeline-rid211401", "raw_data.csv")
  File "/opt/airflow/dags/etl_pipeline.py", line 8, in read_raw_csv_from_s3
    obj = s3.get_object(Bucket=bucket_name, Key=key)
  File "/home/airflow/.local/lib/python3.10/site-packages/botocore/client.py", line 553, in _api_call
    return self._make_api_call(operation_name, kwargs)
  File "/home/airflow/.local/lib/python3.10/site-packages/botocore/client.py", line 989, in _make_api_call
    http, parsed_response = self._make_request(
  File "/home/airflow/.local/lib/python3.10/site-packages/botocore/client.py", line 1015, in _make_request
    return self._endpoint.make_request(operation_model, request_dict)
  File "/home/airflow/.local/lib/python3.10/site-packages/botocore/endpoint.py", line 119, in make_request
    return self._send_request(request_dict, operation_model)
  File "/home/airflow/.local/lib/python3.10/site-packages/botocore/endpoint.py", line 198, in _send_request
    request = self.create_request(request_dict, operation_model)
  File "/home/airflow/.local/lib/python3.10/site-packages/botocore/endpoint.py", line 134, in create_request
    self._event_emitter.emit(
  File "/home/airflow/.local/lib/python3.10/site-packages/botocore/hooks.py", line 412, in emit
    return self._emitter.emit(aliased_event_name, **kwargs)
  File "/home/airflow/.local/lib/python3.10/site-packages/botocore/hooks.py", line 256, in emit
    return self._emit(event_name, kwargs)
  File "/home/airflow/.local/lib/python3.10/site-packages/botocore/hooks.py", line 239, in _emit
    response = handler(**kwargs)
  File "/home/airflow/.local/lib/python3.10/site-packages/botocore/signers.py", line 105, in handler
    return self.sign(operation_name, request)
  File "/home/airflow/.local/lib/python3.10/site-packages/botocore/signers.py", line 195, in sign
    auth.add_auth(request)
  File "/home/airflow/.local/lib/python3.10/site-packages/botocore/auth.py", line 418, in add_auth
    raise NoCredentialsError()
botocore.exceptions.NoCredentialsError: Unable to locate credentials
[2025-07-25T18:44:59.682+0000] {taskinstance.py:1206} INFO - Marking task as UP_FOR_RETRY. dag_id=dnc_pipeline, task_id=executar_pipeline_etl, run_id=manual__2025-07-25T18:44:56.147161+00:00, execution_date=20250725T184456, start_date=20250725T184457, end_date=20250725T184459
[2025-07-25T18:44:59.686+0000] {standard_task_runner.py:110} ERROR - Failed to execute job 6 for task executar_pipeline_etl (Unable to locate credentials; 199)
[2025-07-25T18:44:59.698+0000] {local_task_job_runner.py:240} INFO - Task exited with return code 1
[2025-07-25T18:44:59.704+0000] {taskinstance.py:3498} INFO - 0 downstream tasks scheduled from follow-on schedule check
[2025-07-25T18:44:59.705+0000] {local_task_job_runner.py:222} INFO - ::endgroup::
